Workbook

Sheet Eval Data
A1: IDENTIFICATION | E1: TEMPLATE STRUCTURE | I1: TRACK & STYLE | M1: ILLUSTRATION / SCENE | S1: INTENSITY | T1: GENERATED PROMPTS | Y1: GEMINI EVALUATION | AA1: QA SCORING — PART B
A2: Unique Code | B2: Timestamp | C2: Evaluator | D2: Platform Tested | E2: Archetype | F2: Frame / Overlay Type | G2: Layout | H2: Overlay Strength (B1) | I2: Track | J2: Colour Palette | K2: Background Finish | L2: Render Style | M2: Illustration / Scene Main | N2: Illus Size (A1) | O2: Frame Decoration | P2: Motif | Q2: Accents / Supporting | R2: Mood (B1) | S2: Intensity | T2: Prompt — Firefly (w/ Text) | U2: Prompt — Firefly (No Text) | V2: Prompt — Midjourney | W2: Prompt — Leonardo | X2: Prompt — Gemini | Y2: AI Eval Prompt | Z2: AI Model Response | AA2: ① Overall Score (1–5) | AB2: ② Main Element (Y/P/N) | AC2: ② Supporting (Y/P/N) | AD2: ② Track Style (Y/N) | AE2: ② Mood/Light (Y/N) | AF2: ② Text Zone (Y/N) | AG2: ③ Colour Harmony (1–5) | AH2: ③ WhatsApp-Ready (Y/N) | AI2: ④ Failure Tag | AJ2: ⑤ Notes
A3: Auto from wizard export (DDMM-ARCH-TRACK-LAYOUT-…) | B3: Auto from wizard | C3: Your name | D3: Select from dropdown | E3: A1 / A2 / B1 | F3: A1: F1–F5 | B1: O1–O5 | A2: — | G3: L1–L6 | H3: Light / Heavy — B1 only | I3: A–E | J3: A1/A2 only | K3: A1/A2 only | L3: A1/A2 only | M3: Main illustration (A1/A2) or main scene element (B1) | N3: Small / Medium / Large — A1 only | O3: Plain / Simple / Detailed — A1/A2 only | P3: A1/A2 only | Q3: A2: accent count | B1: supporting scene elements | R3: B1 only — Golden Warm, Misty Soft, etc. | S3: Preset name (Basic / Medium / Complex / etc.) | T3: Full prompt — ≤950 chars | U3: Full prompt — ≤950 chars | V3: Full prompt with --ar flags | W3: Full prompt — ≤1400 chars | X3: Full prompt — no char limit | Y3: Auto from wizard — paste + image into Gemini / Claude / ChatGPT to get a score | Z3: ← Paste the AI model's response here (score + issues) | AA3: 1=Unusable 2=Poor 3=OK 4=Good 5=Ship it | AB3: Y=Yes P=Partial N=Missing | AC3: Y=Yes P=Partial N=Missing/N/A | AD3: Does it match the intended track? | AE3: Lighting + colour matches selection? | AF3: Clear uncluttered text area? | AG3: 1=Clashing 3=OK 5=Beautiful | AH3: Would a real Indian user share this? | AI3: Primary failure reason (select from list) | AJ3: Free text — what went wrong or right

Sheet Instructions
B2: Prompt Evaluation Framework — Instructions v2
B4: 📋 HOW TO USE — STEP BY STEP
B5: Step 1 — Generate | C5: Open the HTML wizard. Walk through all steps and generate prompts.
B6: Step 2 — Export Row | C6: Click 📋 Export Eval Row. Go to Eval Data tab → click cell A4 (or next empty row) → Paste (Cmd+V). All auto-fill columns populate.
B7: Step 3 — Platform | C7: Fill col D (Platform Tested) from dropdown: which AI platform you ran the prompt on.
B8: Step 4 — Run Prompt | C8: Paste the platform-specific prompt from the Excel into Midjourney / Leonardo / Firefly / Gemini. Save the generated image.
B9: Step 5 — AI Eval | C9: Col Y (AI Eval Prompt) is auto-filled when you export the row. Copy it → open Gemini / Claude / ChatGPT → paste the prompt → attach the generated image → send. The prompt already has the Firefly generation prompt embedded. If you tested a different platform, paste that platform's prompt (from cols T–X) in place of it.
B10: Step 6 — Paste Response | C10: Copy the AI model's full response. Paste it into col Z (AI Model Response) for that row.
B11: Step 7 — Score | C11: Fill col AA (Overall Score 1–5) manually. Also fill element check dropdowns (cols AB–AF) and col AH (WhatsApp-Ready).
B12: Step 8 — Repeat | C12: Same combo tested on 4 platforms = 4 rows (one per platform). Paste the same row 4 times, change col D each time.
B14: 🔑 UNIQUE CODE — FORMAT GUIDE
B15: Format | C15: DDMM-[ARCH+STEP2]-[TRACK]-[LAYOUT]-[PAL]-[ILLUS]-[EXTRAS]-[INTENSITY]
B16: A1 example | C16: 2904-A1F2-B-L3-C2-SCC-Si-Md-Me
B17: → decoded | C17: 29 Apr · A1 Dual Band frame · Modern Desi · Text Left · Soft Dawn · Steaming Chai Cup · Simple deco · Medium size · Medium intensity
B18: A2 example | C18: 2904-A2-D-L1-C5-LD-1ac-Bl
B19: → decoded | C19: 29 Apr · A2 · Artsy Playful · Text Top · Sacred Saffron · Lit Diya · 1 accent prop · Balanced intensity
B20: B1 example | C20: 2904-B1O2-E-L1-SCC-M1-Lt-Me
B21: → decoded | C21: 29 Apr · B1 Gradient-Top overlay · Soft & Warm · Text Top · Steaming Chai Cup · Golden Warm mood · Light overlay · Medium intensity
B22: ARCH+STEP2 codes | C22: A1F1–F5 | A2 (no step2 ID) | B1O1–O5
B23: TRACK codes | C23: A=Shiny Maximal B=Modern Desi C=Minimalist D=Artsy Playful E=Soft & Warm
B24: INTENSITY abbr | C24: Ba=Basic Me/Bl=Medium/Balanced Co/Ex/Mx/Ri=Complex variants Mn=Minimal
B25: FRAME DECO abbr | C25: Pl=Plain Si=Simple Dt=Detailed
B26: ILLUS SIZE abbr | C26: Sm=Small Md=Medium Lg=Large
... B29: ILLUS abbr | C29: First letter of each word in illustration name, uppercase, max 4 chars
B31: 📊 SCORING GUIDE — PART B
B32: ① Overall Score (1–5) | C32: 1=Unusable (major failure) 2=Poor (needs significant rework) 3=Decent (usable with tweaks) 4=Good (minor issues) 5=Ship it (production ready)
B33: ② Main Element (Y/P/N) | C33: Y=Clearly visible and well-rendered P=Partial (distorted/blurry/partially wrong) N=Missing entirely
B34: ② Supporting (Y/P/N) | C34: Same scale. Mark N/A as N if no supporting elements were selected.
B35: ② Track Style (Y/N) | C35: Does the overall aesthetic feel match the selected track? (e.g. Modern Desi = muted earthy editorial)
B36: ② Mood/Light (Y/N) | C36: Does the lighting + colour grading match the mood selection? (B1 primary; A1/A2 = colour palette match)
B37: ② Text Zone (Y/N) | C37: Is there a visually clear, uncluttered area suitable for text overlay in the expected position?
B38: ③ Colour Harmony (1–5) | C38: 1=Colours clash badly 2=Somewhat off 3=Acceptable 4=Good harmony 5=Beautiful, cohesive palette
B39: ③ WhatsApp-Ready (Y/N) | C39: Honest gut check: would a real Indian WhatsApp user forward this as a Good Morning greeting?
B40: ④ Failure Tag | C40: Select the PRIMARY reason for failure (or None). Use Notes for more detail.
B41: ⑤ Notes | C41: Free text. What specifically went wrong? Any prompt tweak ideas? What worked well?
B43: 💡 TIPS FOR QA EFFICIENCY
B44: Batch testing | C44: Test all 5 platforms for one combo before moving to the next. Paste same row 5 times, change col D.
B45: Filter by archetype | C45: Use col E (Archetype) filter to compare A1 vs A2 vs B1 results separately.
B46: Sort by score | C46: Sort col AA (Overall Score) ascending to find worst combos fast.
B47: Filter by Failure Tag | C47: Filter col AI to group systemic issues (e.g. all "Text zone blocked" rows).
...

Sheet Dashboard
B2: 📊 Prompt Eval Dashboard
B4: BY ARCHETYPE
B5: Archetype | C5: Avg Score | D5: Runs | E5: WA-Ready % | F5: Main Hit % | G5: Colour Avg
B6: A1 — Text + Frame | C6: =IFERROR(AVERAGEIF('Eval Data'!E$4:E$203,"A1",'Eval Data'!AA$4:AA$203),"—") | D6: =COUNTIF('Eval Data'!E$4:E$203,"A1") | E6: =IFERROR(COUNTIFS('Eval Data'!E$4:E$203,"A1",'Eval Data'!AH$4:AH$203,"Y")/COUNTIF('Eval Data'!E$4:E$203,"A1")*100,"—") | F6: =IFERROR(COUNTIFS('Eval Data'!E$4:E$203,"A1",'Eval Data'!AB$4:AB$203,"Y")/COUNTIF('Eval Data'!E$4:E$203,"A1")*100,"—") | G6: =IFERROR(AVERAGEIF('Eval Data'!E$4:E$203,"A1",'Eval Data'!AG$4:AG$203),"—")
B7: A2 — Illustrations | C7: =IFERROR(AVERAGEIF('Eval Data'!E$4:E$203,"A2",'Eval Data'!AA$4:AA$203),"—") | D7: =COUNTIF('Eval Data'!E$4:E$203,"A2") | E7: =IFERROR(COUNTIFS('Eval Data'!E$4:E$203,"A2",'Eval Data'!AH$4:AH$203,"Y")/COUNTIF('Eval Data'!E$4:E$203,"A2")*100,"—") | F7: =IFERROR(COUNTIFS('Eval Data'!E$4:E$203,"A2",'Eval Data'!AB$4:AB$203,"Y")/COUNTIF('Eval Data'!E$4:E$203,"A2")*100,"—") | G7: =IFERROR(AVERAGEIF('Eval Data'!E$4:E$203,"A2",'Eval Data'!AG$4:AG$203),"—")
B8: B1 — Photo BG | C8: =IFERROR(AVERAGEIF('Eval Data'!E$4:E$203,"B1",'Eval Data'!AA$4:AA$203),"—") | D8: =COUNTIF('Eval Data'!E$4:E$203,"B1") | E8: =IFERROR(COUNTIFS('Eval Data'!E$4:E$203,"B1",'Eval Data'!AH$4:AH$203,"Y")/COUNTIF('Eval Data'!E$4:E$203,"B1")*100,"—") | F8: =IFERROR(COUNTIFS('Eval Data'!E$4:E$203,"B1",'Eval Data'!AB$4:AB$203,"Y")/COUNTIF('Eval Data'!E$4:E$203,"B1")*100,"—") | G8: =IFERROR(AVERAGEIF('Eval Data'!E$4:E$203,"B1",'Eval Data'!AG$4:AG$203),"—")
B10: BY TRACK
B11: Track | C11: Avg Score | D11: Runs | E11: WA-Ready % | F11: Main Hit % | G11: Colour Avg
B12: A — Shiny Maximal | C12: =IFERROR(AVERAGEIF('Eval Data'!I$4:I$203,"*Shiny Maximal*",'Eval Data'!AA$4:AA$203),"—") | D12: =COUNTIF('Eval Data'!I$4:I$203,"*Shiny Maximal*") | E12: =IFERROR(COUNTIFS('Eval Data'!I$4:I$203,"*Shiny Maximal*",'Eval Data'!AH$4:AH$203,"Y")/COUNTIF('Eval Data'!I$4:I$203,"*Shiny Maximal*")*100,"—") | F12: =IFERROR(COUNTIFS('Eval Data'!I$4:I$203,"*Shiny Maximal*",'Eval Data'!AB$4:AB$203,"Y")/COUNTIF('Eval Data'!I$4:I$203,"*Shiny Maximal*")*100,"—") | G12: =IFERROR(AVERAGEIF('Eval Data'!I$4:I$203,"*Shiny Maximal*",'Eval Data'!AG$4:AG$203),"—")
B13: B — Modern Desi | C13: =IFERROR(AVERAGEIF('Eval Data'!I$4:I$203,"*Modern Desi*",'Eval Data'!AA$4:AA$203),"—") | D13: =COUNTIF('Eval Data'!I$4:I$203,"*Modern Desi*") | E13: =IFERROR(COUNTIFS('Eval Data'!I$4:I$203,"*Modern Desi*",'Eval Data'!AH$4:AH$203,"Y")/COUNTIF('Eval Data'!I$4:I$203,"*Modern Desi*")*100,"—") | F13: =IFERROR(COUNTIFS('Eval Data'!I$4:I$203,"*Modern Desi*",'Eval Data'!AB$4:AB$203,"Y")/COUNTIF('Eval Data'!I$4:I$203,"*Modern Desi*")*100,"—") | G13: =IFERROR(AVERAGEIF('Eval Data'!I$4:I$203,"*Modern Desi*",'Eval Data'!AG$4:AG$203),"—")
B14: C — Minimalist Classy | C14: =IFERROR(AVERAGEIF('Eval Data'!I$4:I$203,"*Minimalist Classy*",'Eval Data'!AA$4:AA$203),"—") | D14: =COUNTIF('Eval Data'!I$4:I$203,"*Minimalist Classy*") | E14: =IFERROR(COUNTIFS('Eval Data'!I$4:I$203,"*Minimalist Classy*",'Eval Data'!AH$4:AH$203,"Y")/COUNTIF('Eval Data'!I$4:I$203,"*Minimalist Classy*")*100,"—") | F14: =IFERROR(COUNTIFS('Eval Data'!I$4:I$203,"*Minimalist Classy*",'Eval Data'!AB$4:AB$203,"Y")/COUNTIF('Eval Data'!I$4:I$203,"*Minimalist Classy*")*100,"—") | G14: =IFERROR(AVERAGEIF('Eval Data'!I$4:I$203,"*Minimalist Classy*",'Eval Data'!AG$4:AG$203),"—")
B15: D — Artsy Playful | C15: =IFERROR(AVERAGEIF('Eval Data'!I$4:I$203,"*Artsy Playful*",'Eval Data'!AA$4:AA$203),"—") | D15: =COUNTIF('Eval Data'!I$4:I$203,"*Artsy Playful*") | E15: =IFERROR(COUNTIFS('Eval Data'!I$4:I$203,"*Artsy Playful*",'Eval Data'!AH$4:AH$203,"Y")/COUNTIF('Eval Data'!I$4:I$203,"*Artsy Playful*")*100,"—") | F15: =IFERROR(COUNTIFS('Eval Data'!I$4:I$203,"*Artsy Playful*",'Eval Data'!AB$4:AB$203,"Y")/COUNTIF('Eval Data'!I$4:I$203,"*Artsy Playful*")*100,"—") | G15: =IFERROR(AVERAGEIF('Eval Data'!I$4:I$203,"*Artsy Playful*",'Eval Data'!AG$4:AG$203),"—")
B16: E — Soft & Warm | C16: =IFERROR(AVERAGEIF('Eval Data'!I$4:I$203,"*Soft & Warm*",'Eval Data'!AA$4:AA$203),"—") | D16: =COUNTIF('Eval Data'!I$4:I$203,"*Soft & Warm*") | E16: =IFERROR(COUNTIFS('Eval Data'!I$4:I$203,"*Soft & Warm*",'Eval Data'!AH$4:AH$203,"Y")/COUNTIF('Eval Data'!I$4:I$203,"*Soft & Warm*")*100,"—") | F16: =IFERROR(COUNTIFS('Eval Data'!I$4:I$203,"*Soft & Warm*",'Eval Data'!AB$4:AB$203,"Y")/COUNTIF('Eval Data'!I$4:I$203,"*Soft & Warm*")*100,"—") | G16: =IFERROR(AVERAGEIF('Eval Data'!I$4:I$203,"*Soft & Warm*",'Eval Data'!AG$4:AG$203),"—")
B18: BY PLATFORM
B19: Platform | C19: Avg Score | D19: Runs | E19: WA-Ready % | F19: Main Hit % | G19: Colour Avg
B20: Midjourney | C20: =IFERROR(AVERAGEIF('Eval Data'!D$4:D$203,"*Midjourney*",'Eval Data'!AA$4:AA$203),"—") | D20: =COUNTIF('Eval Data'!D$4:D$203,"*Midjourney*") | E20: =IFERROR(COUNTIFS('Eval Data'!D$4:D$203,"*Midjourney*",'Eval Data'!AH$4:AH$203,"Y")/COUNTIF('Eval Data'!D$4:D$203,"*Midjourney*")*100,"—") | F20: =IFERROR(COUNTIFS('Eval Data'!D$4:D$203,"*Midjourney*",'Eval Data'!AB$4:AB$203,"Y")/COUNTIF('Eval Data'!D$4:D$203,"*Midjourney*")*100,"—") | G20: =IFERROR(AVERAGEIF('Eval Data'!D$4:D$203,"*Midjourney*",'Eval Data'!AG$4:AG$203),"—")
B21: Leonardo.AI | C21: =IFERROR(AVERAGEIF('Eval Data'!D$4:D$203,"*Leonardo.AI*",'Eval Data'!AA$4:AA$203),"—") | D21: =COUNTIF('Eval Data'!D$4:D$203,"*Leonardo.AI*") | E21: =IFERROR(COUNTIFS('Eval Data'!D$4:D$203,"*Leonardo.AI*",'Eval Data'!AH$4:AH$203,"Y")/COUNTIF('Eval Data'!D$4:D$203,"*Leonardo.AI*")*100,"—") | F21: =IFERROR(COUNTIFS('Eval Data'!D$4:D$203,"*Leonardo.AI*",'Eval Data'!AB$4:AB$203,"Y")/COUNTIF('Eval Data'!D$4:D$203,"*Leonardo.AI*")*100,"—") | G21: =IFERROR(AVERAGEIF('Eval Data'!D$4:D$203,"*Leonardo.AI*",'Eval Data'!AG$4:AG$203),"—")
B22: Adobe Firefly (w/ Text) | C22: =IFERROR(AVERAGEIF('Eval Data'!D$4:D$203,"*Adobe Firefly (Text)*",'Eval Data'!AA$4:AA$203),"—") | D22: =COUNTIF('Eval Data'!D$4:D$203,"*Adobe Firefly (Text)*") | E22: =IFERROR(COUNTIFS('Eval Data'!D$4:D$203,"*Adobe Firefly (Text)*",'Eval Data'!AH$4:AH$203,"Y")/COUNTIF('Eval Data'!D$4:D$203,"*Adobe Firefly (Text)*")*100,"—") | F22: =IFERROR(COUNTIFS('Eval Data'!D$4:D$203,"*Adobe Firefly (Text)*",'Eval Data'!AB$4:AB$203,"Y")/COUNTIF('Eval Data'!D$4:D$203,"*Adobe Firefly (Text)*")*100,"—") | G22: =IFERROR(AVERAGEIF('Eval Data'!D$4:D$203,"*Adobe Firefly (Text)*",'Eval Data'!AG$4:AG$203),"—")
B23: Adobe Firefly (No Text) | C23: =IFERROR(AVERAGEIF('Eval Data'!D$4:D$203,"*Adobe Firefly (No Text)*",'Eval Data'!AA$4:AA$203),"—") | D23: =COUNTIF('Eval Data'!D$4:D$203,"*Adobe Firefly (No Text)*") | E23: =IFERROR(COUNTIFS('Eval Data'!D$4:D$203,"*Adobe Firefly (No Text)*",'Eval Data'!AH$4:AH$203,"Y")/COUNTIF('Eval Data'!D$4:D$203,"*Adobe Firefly (No Text)*")*100,"—") | F23: =IFERROR(COUNTIFS('Eval Data'!D$4:D$203,"*Adobe Firefly (No Text)*",'Eval Data'!AB$4:AB$203,"Y")/COUNTIF('Eval Data'!D$4:D$203,"*Adobe Firefly (No Text)*")*100,"—") | G23: =IFERROR(AVERAGEIF('Eval Data'!D$4:D$203,"*Adobe Firefly (No Text)*",'Eval Data'!AG$4:AG$203),"—")
B24: Google Gemini | C24: =IFERROR(AVERAGEIF('Eval Data'!D$4:D$203,"*Google Gemini*",'Eval Data'!AA$4:AA$203),"—") | D24: =COUNTIF('Eval Data'!D$4:D$203,"*Google Gemini*") | E24: =IFERROR(COUNTIFS('Eval Data'!D$4:D$203,"*Google Gemini*",'Eval Data'!AH$4:AH$203,"Y")/COUNTIF('Eval Data'!D$4:D$203,"*Google Gemini*")*100,"—") | F24: =IFERROR(COUNTIFS('Eval Data'!D$4:D$203,"*Google Gemini*",'Eval Data'!AB$4:AB$203,"Y")/COUNTIF('Eval Data'!D$4:D$203,"*Google Gemini*")*100,"—") | G24: =IFERROR(AVERAGEIF('Eval Data'!D$4:D$203,"*Google Gemini*",'Eval Data'!AG$4:AG$203),"—")
B26: BY MOOD — B1 ONLY
B27: Mood | C27: Avg Score | D27: Runs | E27: WA-Ready % | F27: Main Hit %
B28: Golden Warm | C28: =IFERROR(AVERAGEIF('Eval Data'!R$4:R$203,"*Golden Warm*",'Eval Data'!AA$4:AA$203),"—") | D28: =COUNTIF('Eval Data'!R$4:R$203,"*Golden Warm*") | E28: =IFERROR(COUNTIFS('Eval Data'!R$4:R$203,"*Golden Warm*",'Eval Data'!AH$4:AH$203,"Y")/COUNTIF('Eval Data'!R$4:R$203,"*Golden Warm*")*100,"—") | F28: =IFERROR(COUNTIFS('Eval Data'!R$4:R$203,"*Golden Warm*",'Eval Data'!AB$4:AB$203,"Y")/COUNTIF('Eval Data'!R$4:R$203,"*Golden Warm*")*100,"—")
B29: Misty Soft | C29: =IFERROR(AVERAGEIF('Eval Data'!R$4:R$203,"*Misty Soft*",'Eval Data'!AA$4:AA$203),"—") | D29: =COUNTIF('Eval Data'!R$4:R$203,"*Misty Soft*") | E29: =IFERROR(COUNTIFS('Eval Data'!R$4:R$203,"*Misty Soft*",'Eval Data'!AH$4:AH$203,"Y")/COUNTIF('Eval Data'!R$4:R$203,"*Misty Soft*")*100,"—") | F29: =IFERROR(COUNTIFS('Eval Data'!R$4:R$203,"*Misty Soft*",'Eval Data'!AB$4:AB$203,"Y")/COUNTIF('Eval Data'!R$4:R$203,"*Misty Soft*")*100,"—")
B30: Bright & Vivid | C30: =IFERROR(AVERAGEIF('Eval Data'!R$4:R$203,"*Bright & Vivid*",'Eval Data'!AA$4:AA$203),"—") | D30: =COUNTIF('Eval Data'!R$4:R$203,"*Bright & Vivid*") | E30: =IFERROR(COUNTIFS('Eval Data'!R$4:R$203,"*Bright & Vivid*",'Eval Data'!AH$4:AH$203,"Y")/COUNTIF('Eval Data'!R$4:R$203,"*Bright & Vivid*")*100,"—") | F30: =IFERROR(COUNTIFS('Eval Data'!R$4:R$203,"*Bright & Vivid*",'Eval Data'!AB$4:AB$203,"Y")/COUNTIF('Eval Data'!R$4:R$203,"*Bright & Vivid*")*100,"—")
B31: Dramatic Rays | C31: =IFERROR(AVERAGEIF('Eval Data'!R$4:R$203,"*Dramatic Rays*",'Eval Data'!AA$4:AA$203),"—") | D31: =COUNTIF('Eval Data'!R$4:R$203,"*Dramatic Rays*") | E31: =IFERROR(COUNTIFS('Eval Data'!R$4:R$203,"*Dramatic Rays*",'Eval Data'!AH$4:AH$203,"Y")/COUNTIF('Eval Data'!R$4:R$203,"*Dramatic Rays*")*100,"—") | F31: =IFERROR(COUNTIFS('Eval Data'!R$4:R$203,"*Dramatic Rays*",'Eval Data'!AB$4:AB$203,"Y")/COUNTIF('Eval Data'!R$4:R$203,"*Dramatic Rays*")*100,"—")
B32: Vintage Film | C32: =IFERROR(AVERAGEIF('Eval Data'!R$4:R$203,"*Vintage Film*",'Eval Data'!AA$4:AA$203),"—") | D32: =COUNTIF('Eval Data'!R$4:R$203,"*Vintage Film*") | E32: =IFERROR(COUNTIFS('Eval Data'!R$4:R$203,"*Vintage Film*",'Eval Data'!AH$4:AH$203,"Y")/COUNTIF('Eval Data'!R$4:R$203,"*Vintage Film*")*100,"—") | F32: =IFERROR(COUNTIFS('Eval Data'!R$4:R$203,"*Vintage Film*",'Eval Data'!AB$4:AB$203,"Y")/COUNTIF('Eval Data'!R$4:R$203,"*Vintage Film*")*100,"—")
B33: Soft Pastel | C33: =IFERROR(AVERAGEIF('Eval Data'!R$4:R$203,"*Soft Pastel*",'Eval Data'!AA$4:AA$203),"—") | D33: =COUNTIF('Eval Data'!R$4:R$203,"*Soft Pastel*") | E33: =IFERROR(COUNTIFS('Eval Data'!R$4:R$203,"*Soft Pastel*",'Eval Data'!AH$4:AH$203,"Y")/COUNTIF('Eval Data'!R$4:R$203,"*Soft Pastel*")*100,"—") | F33: =IFERROR(COUNTIFS('Eval Data'!R$4:R$203,"*Soft Pastel*",'Eval Data'!AB$4:AB$203,"Y")/COUNTIF('Eval Data'!R$4:R$203,"*Soft Pastel*")*100,"—")
B35: TOP FAILURE TAGS (counts)
B36: Failure Tag | C36: Count
B37: Missing main element | C37: =COUNTIF('Eval Data'!AI$4:AI$203,"*Missing main element*")
B38: Supporting element missing | C38: =COUNTIF('Eval Data'!AI$4:AI$203,"*Supporting element missing*")
B39: Wrong track style | C39: =COUNTIF('Eval Data'!AI$4:AI$203,"*Wrong track style*")
B40: Colour mismatch | C40: =COUNTIF('Eval Data'!AI$4:AI$203,"*Colour mismatch*")
B41: Text zone blocked | C41: =COUNTIF('Eval Data'!AI$4:AI$203,"*Text zone blocked*")
B42: Frame structure wrong | C42: =COUNTIF('Eval Data'!AI$4:AI$203,"*Frame structure wrong*")
B43: Illustration size wrong | C43: =COUNTIF('Eval Data'!AI$4:AI$203,"*Illustration size wrong*")
B44: Lighting/mood mismatch | C44: =COUNTIF('Eval Data'!AI$4:AI$203,"*Lighting/mood mismatch*")
B45: Bad render style | C45: =COUNTIF('Eval Data'!AI$4:AI$203,"*Bad render style*")
B46: AI text visible | C46: =COUNTIF('Eval Data'!AI$4:AI$203,"*AI text visible*")
...
